<?xml version="1.0" encoding="utf-8"?>
<!-- This URDF was automatically created by SolidWorks to URDF Exporter! Originally created by Stephen Brawner (brawner@gmail.com) 
     Commit Version: 1.6.0-4-g7f85cfe  Build Version: 1.6.7995.38578
     For more information, please see http://wiki.ros.org/sw_urdf_exporter -->
<robot
  name="piper_description">
  <link
    name="base_link">
    <inertial>
      <origin
        xyz="-0.00973928490005031 1.83127089286717E-06 0.0410140167677137"
        rpy="0 0 0" />
      <mass
        value="0.0001" />
      <inertia
        ixx="0.000226592553127906"
        ixy="-7.33974356968615E-08"
        ixz="2.13221970218122E-06"
        iyy="0.000269447877479622"
        iyz="8.15167478682596E-09"
        izz="0.000222318286704" />
    </inertial>
    <visual>
      <origin
        xyz="0 0 0"
        rpy="1.5708 0 -1.5708" />
      <geometry>
        <mesh
          filename="package://piper_description/meshes/base_link.dae" />
      </geometry>
      <material
        name="">
        <color
          rgba="0.792156862745098 0.819607843137255 0.933333333333333 1" />
      </material>
    </visual>
    <collision>
      <origin
        xyz="0 0 0"
        rpy="0 0 0" />
      <geometry>
        <mesh
          filename="package://piper_description/meshes/base_link.STL" />
      </geometry>
    </collision>
  </link>
  <link
    name="link1">
    <inertial>
      <origin
        xyz="0.00131676031927021 0.000310288842008365 -0.00922874512303438"
        rpy="0 0 0" />
      <mass
        value="0.0001" />
      <inertia
        ixx="7.76684558296782E-05"
        ixy="1.09084650459916E-07"
        ixz="-1.97480532432411E-06"
        iyy="9.24967780161546E-05"
        iyz="9.91284646834672E-07"
        izz="8.24589062407806E-05" />
    </inertial>
    <visual>
      <origin
        xyz="0 0 0"
        rpy="1.5708 0 0" />
      <geometry>
        <mesh
          filename="package://piper_description/meshes/link1.dae" />
      </geometry>
      <material
        name="">
        <color
          rgba="0.792156862745098 0.819607843137255 0.933333333333333 1" />
      </material>
    </visual>
    <collision>
      <origin
        xyz="0 0 0"
        rpy="0 0 0" />
      <geometry>
        <mesh
          filename="package://piper_description/meshes/link1.STL" />
      </geometry>
    </collision>
  </link>
  <joint
    name="joint1"
    type="revolute">
    <origin
      xyz="0 0 0.123"
      rpy="0 0 -1.5708" />
    <parent
      link="base_link" />
    <child
      link="link1" />
    <axis
      xyz="0 0 1" />
    <limit
      lower="-2.618"
      upper="2.618"
      effort="100"
      velocity="3" />
  </joint>
  <link
    name="link2">
    <inertial>
      <origin
        xyz="0.147615838821413 -0.0174259998251394 0.00175952516190707"
        rpy="0 0 0" />
      <mass
        value="0.0001" />
      <inertia
        ixx="0.000150112628108228"
        ixy="8.58974959950769E-05"
        ixz="-1.07428153464284E-06"
        iyy="0.00172585302855383"
        iyz="-9.93704792239676E-07"
        izz="0.00177445942914759" />
    </inertial>
    <visual>
      <origin
        xyz="0 0 0"
        rpy="0 1.5708 -0.0873" />
      <geometry>
        <mesh
          filename="package://piper_description/meshes/link2.dae" />
      </geometry>
      <material
        name="">
        <color
          rgba="0.792156862745098 0.819607843137255 0.933333333333333 1" />
      </material>
    </visual>
    <collision>
      <origin
        xyz="0 0 0"
        rpy="0 0 0" />
      <geometry>
        <mesh
          filename="package://piper_description/meshes/link2.STL" />
      </geometry>
    </collision>
  </link>
  <joint
    name="joint2"
    type="revolute">
    <origin
      xyz="0 0 0"
      rpy="1.5708 -0.10095 -1.5708" />
    <parent
      link="link1" />
    <child
      link="link2" />
    <axis
      xyz="0 0 1" />
    <limit
      lower="0"
      upper="3.14"
      effort="100"
      velocity="3" />
  </joint>
  <link
    name="link3">
    <inertial>
      <origin
        xyz="0.0156727239770991 0.104466514402189 0.000508486576356504"
        rpy="0 0 0" />
      <mass
        value="0.0001" />
      <inertia
        ixx="0.00022168634302318"
        ixy="-7.57426147001315E-06"
        ixz="-6.36999759250492E-07"
        iyy="0.000100859159512329"
        iyz="-8.16199264787698E-07"
        izz="0.000241839306422341" />
    </inertial>
    <visual>
      <origin
        xyz="0 0 0"
        rpy="1.4835 1.5708 0" />
      <geometry>
        <mesh
          filename="package://piper_description/meshes/link3.dae" />
      </geometry>
      <material
        name="">
        <color
          rgba="0.792156862745098 0.819607843137255 0.933333333333333 1" />
      </material>
    </visual>
    <collision>
      <origin
        xyz="0 0 0"
        rpy="0 0 0" />
      <geometry>
        <mesh
          filename="package://piper_description/meshes/link3.STL" />
      </geometry>
    </collision>
  </link>
  <joint
    name="joint3"
    type="revolute">
    <origin
      xyz="0.28503 0 0"
      rpy="0 0 1.3826" />
    <parent
      link="link2" />
    <child
      link="link3" />
    <axis
      xyz="0 0 1" />
    <limit
      lower="-2.697"
      upper="0"
      effort="100"
      velocity="3" />
  </joint>
  <link
    name="link4">
    <inertial>
      <origin
        xyz="0.000276464622388145 -0.00102803669324856 -0.00472830700561582"
        rpy="0 0 0" />
      <mass
        value="0.0001" />
      <inertia
        ixx="3.82011730423392E-05"
        ixy="-4.92358350916331E-08"
        ixz="4.89589432971791E-08"
        iyy="4.87048555222583E-05"
        iyz="6.70802942501353E-08"
        izz="4.10592077565539E-05" />
    </inertial>
    <visual>
      <origin
        xyz="0 0 0"
        rpy="1.48 0 1.5708" />
      <geometry>
        <mesh
          filename="package://piper_description/meshes/link4.dae" />
      </geometry>
      <material
        name="">
        <color
          rgba="0.792156862745098 0.819607843137255 0.933333333333333 1" />
      </material>
    </visual>
    <collision>
      <origin
        xyz="0 0 0"
        rpy="0 0 0" />
      <geometry>
        <mesh
          filename="package://piper_description/meshes/link4.STL" />
      </geometry>
    </collision>
  </link>
  <joint
    name="joint4"
    type="revolute">
    <origin
      xyz="0.021984 0.25075 0"
      rpy="-1.5708 0 0" />
    <parent
      link="link3" />
    <child
      link="link4" />
    <axis
      xyz="0 0 1" />
    <limit
      lower="-1.832"
      upper="1.832"
      effort="100"
      velocity="3" />
  </joint>
  <link
    name="link5">
    <inertial>
      <origin
        xyz="8.82262433637704E-05 0.0566829014808264 -0.00196119720482555"
        rpy="0 0 0" />
      <mass
        value="0.0001" />
      <inertia
        ixx="4.39644313661978E-05"
        ixy="-3.59259686449865E-08"
        ixz="-1.89747741592145E-08"
        iyy="5.6317392095077E-05"
        iyz="-2.1540716689678E-07"
        izz="4.88713664675246E-05" />
    </inertial>
    <visual>
      <origin
        xyz="0 0 0"
        rpy="1.4835 1.5708 0" />
      <geometry>
        <mesh
          filename="package://piper_description/meshes/link5.dae" />
      </geometry>
      <material
        name="">
        <color
          rgba="0.792156862745098 0.819607843137255 0.933333333333333 1" />
      </material>
    </visual>
    <collision>
      <origin
        xyz="0 0 0"
        rpy="0 0 0" />
      <geometry>
        <mesh
          filename="package://piper_description/meshes/link5.STL" />
      </geometry>
    </collision>
  </link>
  <joint
    name="joint5"
    type="revolute">
    <origin
      xyz="0 0 0"
      rpy="1.5708 0 0" />
    <parent
      link="link4" />
    <child
      link="link5" />
    <axis
      xyz="0 0 1" />
    <limit
      lower="-1.22"
      upper="1.22"
      effort="100"
      velocity="3" />
  </joint>

</robot>