<?xml version="1.0" encoding="utf-8"?>
<robot
  name="arm"
  xmlns:xacro="http://ros.org/wiki/xacro">
<!-- world -->
  <link name="world"/>
  <joint name="fixed_base_joint" type="fixed">
      <parent link="world"/>
      <child link="base_link"/>
  </joint>
<!-- arm -->
<link
    name="base_link">
    <inertial>
      <origin
        xyz="-0.00973928490005031 1.83127089286717E-06 0.0410140167677137"
        rpy="0 0 0" />
      <mass
        value="0.0001" />
      <inertia
        ixx="0.000226592553127906"
        ixy="-7.33974356968615E-08"
        ixz="2.13221970218122E-06"
        iyy="0.000269447877479622"
        iyz="8.15167478682596E-09"
        izz="0.000222318286704" />
    </inertial>
    <visual>
      <origin
        xyz="0 0 0"
        rpy="1.5708 0 -1.5708" />
      <geometry>
        <mesh
          filename="package://piper_description/meshes/base_link.dae" />
      </geometry>
      <material
        name="">
        <color
          rgba="0.792156862745098 0.819607843137255 0.933333333333333 1" />
      </material>
    </visual>
    <collision>
      <origin
        xyz="0 0 0"
        rpy="0 0 0" />
      <geometry>
        <mesh
          filename="package://piper_description/meshes/base_link.STL" />
      </geometry>
    </collision>
  </link>
  <link
    name="link1">
    <inertial>
      <origin
        xyz="0.00131676031927021 0.000310288842008365 -0.00922874512303438"
        rpy="0 0 0" />
      <mass
        value="0.0001" />
      <inertia
        ixx="7.76684558296782E-05"
        ixy="1.09084650459916E-07"
        ixz="-1.97480532432411E-06"
        iyy="9.24967780161546E-05"
        iyz="9.91284646834672E-07"
        izz="8.24589062407806E-05" />
    </inertial>
    <visual>
      <origin
        xyz="0 0 0"
        rpy="1.5708 0 0" />
      <geometry>
        <mesh
          filename="package://piper_description/meshes/link1.dae" />
      </geometry>
      <material
        name="">
        <color
          rgba="0.792156862745098 0.819607843137255 0.933333333333333 1" />
      </material>
    </visual>
    <collision>
      <origin
        xyz="0 0 0"
        rpy="0 0 0" />
      <geometry>
        <mesh
          filename="package://piper_description/meshes/link1.STL" />
      </geometry>
    </collision>
  </link>
  <joint
    name="joint1"
    type="revolute">
    <origin
      xyz="0 0 0.123"
      rpy="0 0 -1.5708" />
    <parent
      link="base_link" />
    <child
      link="link1" />
    <axis
      xyz="0 0 1" />
    <limit
      lower="-2.618"
      upper="2.618"
      effort="100"
      velocity="3" />
  </joint>
  <link
    name="link2">
    <inertial>
      <origin
        xyz="0.147615838821413 -0.0174259998251394 0.00175952516190707"
        rpy="0 0 0" />
      <mass
        value="0.0001" />
      <inertia
        ixx="0.000150112628108228"
        ixy="8.58974959950769E-05"
        ixz="-1.07428153464284E-06"
        iyy="0.00172585302855383"
        iyz="-9.93704792239676E-07"
        izz="0.00177445942914759" />
    </inertial>
    <visual>
      <origin
        xyz="0 0 0"
        rpy="0 1.5708 -0.0873" />
      <geometry>
        <mesh
          filename="package://piper_description/meshes/link2.dae" />
      </geometry>
      <material
        name="">
        <color
          rgba="0.792156862745098 0.819607843137255 0.933333333333333 1" />
      </material>
    </visual>
    <collision>
      <origin
        xyz="0 0 0"
        rpy="0 0 0" />
      <geometry>
        <mesh
          filename="package://piper_description/meshes/link2.STL" />
      </geometry>
    </collision>
  </link>
  <joint
    name="joint2"
    type="revolute">
    <origin
      xyz="0 0 0"
      rpy="1.5708 -0.10095 -1.5708" />
    <parent
      link="link1" />
    <child
      link="link2" />
    <axis
      xyz="0 0 1" />
    <limit
      lower="0"
      upper="3.14"
      effort="100"
      velocity="3" />
  </joint>
  <link
    name="link3">
    <inertial>
      <origin
        xyz="0.0156727239770991 0.104466514402189 0.000508486576356504"
        rpy="0 0 0" />
      <mass
        value="0.0001" />
      <inertia
        ixx="0.00022168634302318"
        ixy="-7.57426147001315E-06"
        ixz="-6.36999759250492E-07"
        iyy="0.000100859159512329"
        iyz="-8.16199264787698E-07"
        izz="0.000241839306422341" />
    </inertial>
    <visual>
      <origin
        xyz="0 0 0"
        rpy="1.4835 1.5708 0" />
      <geometry>
        <mesh
          filename="package://piper_description/meshes/link3.dae" />
      </geometry>
      <material
        name="">
        <color
          rgba="0.792156862745098 0.819607843137255 0.933333333333333 1" />
      </material>
    </visual>
    <collision>
      <origin
        xyz="0 0 0"
        rpy="0 0 0" />
      <geometry>
        <mesh
          filename="package://piper_description/meshes/link3.STL" />
      </geometry>
    </collision>
  </link>
  <joint
    name="joint3"
    type="revolute">
    <origin
      xyz="0.28503 0 0"
      rpy="0 0 1.3826" />
    <parent
      link="link2" />
    <child
      link="link3" />
    <axis
      xyz="0 0 1" />
    <limit
      lower="-2.697"
      upper="0"
      effort="100"
      velocity="3" />
  </joint>
  <link
    name="link4">
    <inertial>
      <origin
        xyz="0.000276464622388145 -0.00102803669324856 -0.00472830700561582"
        rpy="0 0 0" />
      <mass
        value="0.0001" />
      <inertia
        ixx="3.82011730423392E-05"
        ixy="-4.92358350916331E-08"
        ixz="4.89589432971791E-08"
        iyy="4.87048555222583E-05"
        iyz="6.70802942501353E-08"
        izz="4.10592077565539E-05" />
    </inertial>
    <visual>
      <origin
        xyz="0 0 0"
        rpy="1.48 0 1.5708" />
      <geometry>
        <mesh
          filename="package://piper_description/meshes/link4.dae" />
      </geometry>
      <material
        name="">
        <color
          rgba="0.792156862745098 0.819607843137255 0.933333333333333 1" />
      </material>
    </visual>
    <collision>
      <origin
        xyz="0 0 0"
        rpy="0 0 0" />
      <geometry>
        <mesh
          filename="package://piper_description/meshes/link4.STL" />
      </geometry>
    </collision>
  </link>
  <joint
    name="joint4"
    type="revolute">
    <origin
      xyz="0.021984 0.25075 0"
      rpy="-1.5708 0 0" />
    <parent
      link="link3" />
    <child
      link="link4" />
    <axis
      xyz="0 0 1" />
    <limit
      lower="-1.832"
      upper="1.832"
      effort="100"
      velocity="3" />
  </joint>
  <link
    name="link5">
    <inertial>
      <origin
        xyz="8.82262433637704E-05 0.0566829014808264 -0.00196119720482555"
        rpy="0 0 0" />
      <mass
        value="0.0001" />
      <inertia
        ixx="4.39644313661978E-05"
        ixy="-3.59259686449865E-08"
        ixz="-1.89747741592145E-08"
        iyy="5.6317392095077E-05"
        iyz="-2.1540716689678E-07"
        izz="4.88713664675246E-05" />
    </inertial>
    <visual>
      <origin
        xyz="0 0 0"
        rpy="1.4835 1.5708 0" />
      <geometry>
        <mesh
          filename="package://piper_description/meshes/link5.dae" />
      </geometry>
      <material
        name="">
        <color
          rgba="0.792156862745098 0.819607843137255 0.933333333333333 1" />
      </material>
    </visual>
    <collision>
      <origin
        xyz="0 0 0"
        rpy="0 0 0" />
      <geometry>
        <mesh
          filename="package://piper_description/meshes/link5.STL" />
      </geometry>
    </collision>
  </link>
  <joint
    name="joint5"
    type="revolute">
    <origin
      xyz="0 0 0"
      rpy="1.5708 0 0" />
    <parent
      link="link4" />
    <child
      link="link5" />
    <axis
      xyz="0 0 1" />
    <limit
      lower="-1.22"
      upper="1.22"
      effort="100"
      velocity="3" />
  </joint>
  <link
    name="link6">
    <inertial>
      <origin
        xyz="1.16933298222217E-08 0.00034121124902961 0.0342122963963336"
        rpy="0 0 0" />
      <mass
        value="0.0001" />
      <inertia
        ixx="4.31750624665837E-05"
        ixy="-2.21358545270113E-08"
        ixz="-4.12717194808373E-12"
        iyy="9.99756712688719E-05"
        iyz="1.10337149130826E-07"
        izz="0.000118282337309882" />
    </inertial>
    <visual>
      <origin
        xyz="0 0 0"
        rpy="3.14159 0 3.14159" />
      <geometry>
        <mesh
          filename="package://piper_description/meshes/link6.dae" />
      </geometry>
      <material
        name="">
        <color
          rgba="0.792156862745098 0.819607843137255 0.933333333333333 1" />
      </material>
    </visual>
    <collision>
      <origin
        xyz="0 0 0"
        rpy="0 0 0" />
      <geometry>
        <mesh
          filename="package://piper_description/meshes/link6.STL" />
      </geometry>
    </collision>
  </link>
  <joint
    name="joint6"
    type="revolute">
    <origin
      xyz="0 0.091 0.0014165"
      rpy="-1.5708 -1.5708 0" />
    <parent
      link="link5" />
    <child
      link="link6" />
    <axis
      xyz="0 0 1" />
    <limit
      lower="-3.14"
      upper="3.14"
      effort="100"
      velocity="3" />
  </joint>
  <link
    name="link7">
    <inertial>
      <origin
        xyz="-0.00027777838372664 -0.0467673043652057 -0.00921029491873199"
        rpy="0 0 0" />
      <mass
        value="0.0001" />
      <inertia
        ixx="9.99787479924596E-06"
        ixy="-1.57548495096094E-07"
        ixz="-2.71342775003444E-08"
        iyy="6.17952122936548E-06"
        iyz="-1.58939803580081E-06"
        izz="1.42102717246565E-05" />
    </inertial>
    <visual>
      <origin
        xyz="0 0 0"
        rpy="-0.0873 -1.5708 1.5708" />
      <geometry>
        <mesh
          filename="package://piper_description/meshes/link7.dae" />
      </geometry>
      <material
        name="">
        <color
          rgba="0.792156862745098 0.819607843137255 0.933333333333333 1" />
      </material>
    </visual>
    <collision>
      <origin
        xyz="0 0 0"
        rpy="0 0 0" />
      <geometry>
        <mesh
          filename="package://piper_description/meshes/link7.STL" />
      </geometry>
    </collision>
  </link>
  <joint
    name="joint7"
    type="prismatic">
    <origin
      xyz="-0.0001 0 0.13503"
      rpy="1.5708 0 1.5708" />
    <parent
      link="link6" />
    <child
      link="link7" />
    <axis
      xyz="0 0 -1" />
    <limit
      lower="0"
      upper="0.04"
      effort="10"
      velocity="1" />
  </joint>
  <link
    name="link8">
    <inertial>
      <origin
        xyz="0.000277816920932594 0.0467673824062785 -0.00921030054507634"
        rpy="0 0 0" />
      <mass
        value="0.0001" />
      <inertia
        ixx="9.99779119361565E-06"
        ixy="-1.5754228345079E-07"
        ixz="2.7136744671289E-08"
        iyy="6.17952441558639E-06"
        iyz="1.58939319453633E-06"
        izz="1.42101927545622E-05" />
    </inertial>
    <visual>
      <origin
        xyz="0 0 0"
        rpy="-0.0873 1.5708 1.5708" />
      <geometry>
        <mesh
          filename="package://piper_description/meshes/link8.dae" />
      </geometry>
      <material
        name="">
        <color
          rgba="0.792156862745098 0.819607843137255 0.933333333333333 1" />
      </material>
    </visual>
    <collision>
      <origin
        xyz="0 0 0"
        rpy="0 0 0" />
      <geometry>
        <mesh
          filename="package://piper_description/meshes/link8.STL" />
      </geometry>
    </collision>
  </link>
  <joint
    name="joint8"
    type="prismatic">
    <origin
      xyz="0.0001 0 0.13503"
      rpy="-1.5708 0 1.5708" />
    <parent
      link="link6" />
    <child
      link="link8" />
    <axis
      xyz="0 0 1" />
    <limit
      lower="-0.04"
      upper="0"
      effort="10"
      velocity="1" />
  </joint>

<!-- controller -->
  <xacro:macro name="transmission_block" params="tran_name joint_name motor_name">
    <transmission name="${tran_name}">
        <type>transmission_interface/SimpleTransmission</type>
        <joint name="${joint_name}">
            <hardwareInterface>hardware_interface/PositionJointInterface</hardwareInterface>
        </joint>
        <actuator name="$motor_name">
            <hardwareInterface>hardware_interface/PositionJointInterface</hardwareInterface>
            <mechanicalReduction>1</mechanicalReduction>
        </actuator>
    </transmission>
  </xacro:macro>

  <xacro:transmission_block tran_name="tran1" joint_name="joint1" motor_name="motor1"/>
  <xacro:transmission_block tran_name="tran2" joint_name="joint2" motor_name="motor2"/>
  <xacro:transmission_block tran_name="tran3" joint_name="joint3" motor_name="motor3"/>
  <xacro:transmission_block tran_name="tran4" joint_name="joint4" motor_name="motor4"/>
  <xacro:transmission_block tran_name="tran5" joint_name="joint5" motor_name="motor5"/>
  <xacro:transmission_block tran_name="tran6" joint_name="joint6" motor_name="motor6"/>
  <xacro:transmission_block tran_name="tran7" joint_name="joint7" motor_name="motor7"/>
  <xacro:transmission_block tran_name="tran8" joint_name="joint8" motor_name="motor8"/>
<!-- gazebo -->
  <gazebo>
    <plugin name="gazebo_ros_control" filename="libgazebo_ros_control.so">
        <robotNamespace>/piper_description</robotNamespace>
        <legacyModeNS>true</legacyModeNS>
    </plugin>
  </gazebo>
 
  <gazebo reference="base_link">
    <material>Gazebo/Black</material>
  </gazebo>

  <gazebo reference="link1">
    <material>Gazebo/White</material>
  </gazebo>
 
  <gazebo reference="link2">
    <material>Gazebo/White</material>
  </gazebo>

  <gazebo reference="link3">
    <material>Gazebo/White</material>
  </gazebo>
 
  <gazebo reference="link4">
    <material>Gazebo/Black</material>
  </gazebo>
 
  <gazebo reference="link5">
    <material>Gazebo/White</material>
  </gazebo>
 
  <gazebo reference="link6">
    <material>Gazebo/White</material>
  </gazebo>
 
  <gazebo reference="link7">
    <material>Gazebo/Orange</material>
  </gazebo>
 
  <gazebo reference="link8">
    <material>Gazebo/Orange</material>
  </gazebo>
</robot>